<?xml version="1.0" encoding="UTF-8"?>
<!-- Generated by org.testng.reporters.JUnitReportReporter -->
<testsuite hostname="LAPTOP-7Q4V18QD" failures="2" tests="12" name="RetrylogictestNG.Rtrylogictestcase" time="0.044" errors="0" timestamp="2022-05-24T14:37:19 IST" skipped="10">
  <testcase classname="RetrylogictestNG.Rtrylogictestcase" name="test1" time="0.013">
    <skipped/>
  </testcase> <!-- test1 -->
  <system-out/>
  <testcase classname="RetrylogictestNG.Rtrylogictestcase" name="test1" time="0.001">
    <skipped/>
  </testcase> <!-- test1 -->
  <system-out/>
  <testcase classname="RetrylogictestNG.Rtrylogictestcase" name="test1" time="0.001">
    <skipped/>
  </testcase> <!-- test1 -->
  <system-out/>
  <testcase classname="RetrylogictestNG.Rtrylogictestcase" name="test2" time="0.001">
    <skipped/>
  </testcase> <!-- test2 -->
  <system-out/>
  <testcase classname="RetrylogictestNG.Rtrylogictestcase" name="test2" time="0.003">
    <skipped/>
  </testcase> <!-- test2 -->
  <system-out/>
  <testcase classname="RetrylogictestNG.Rtrylogictestcase" name="test1" time="0.002">
    <skipped/>
  </testcase> <!-- test1 -->
  <system-out/>
  <testcase classname="RetrylogictestNG.Rtrylogictestcase" name="test2" time="0.002">
    <skipped/>
  </testcase> <!-- test2 -->
  <system-out/>
  <testcase classname="RetrylogictestNG.Rtrylogictestcase" name="test1" time="0.002">
    <skipped/>
  </testcase> <!-- test1 -->
  <system-out/>
  <testcase classname="RetrylogictestNG.Rtrylogictestcase" name="test1" time="0.004">
    <failure message="expected [true] but found [flse]" type="java.lang.AssertionError">
      <![CDATA[java.lang.AssertionError: expected [true] but found [flse]
at org.testng.Assert.fail(Assert.java:99)
at org.testng.Assert.failNotEquals(Assert.java:1037)
at org.testng.Assert.assertEqualsImpl(Assert.java:140)
at org.testng.Assert.assertEquals(Assert.java:122)
at org.testng.Assert.assertEquals(Assert.java:629)
at org.testng.Assert.assertEquals(Assert.java:639)
at RetrylogictestNG.Rtrylogictestcase.test1(Rtrylogictestcase.java:10)
at java.base/jdk.internal.reflect.NativeMethodAccessorImpl.invoke0(Native Method)
at java.base/jdk.internal.reflect.NativeMethodAccessorImpl.invoke(NativeMethodAccessorImpl.java:77)
at java.base/jdk.internal.reflect.DelegatingMethodAccessorImpl.invoke(DelegatingMethodAccessorImpl.java:43)
at java.base/java.lang.reflect.Method.invoke(Method.java:568)
at org.testng.internal.MethodInvocationHelper.invokeMethod(MethodInvocationHelper.java:133)
at org.testng.internal.TestInvoker.invokeMethod(TestInvoker.java:598)
at org.testng.internal.TestInvoker.retryFailed(TestInvoker.java:213)
at org.testng.internal.MethodRunner.runInSequence(MethodRunner.java:58)
at org.testng.internal.TestInvoker$MethodInvocationAgent.invoke(TestInvoker.java:824)
at org.testng.internal.TestInvoker.invokeTestMethods(TestInvoker.java:146)
at org.testng.internal.TestMethodWorker.invokeTestMethods(TestMethodWorker.java:146)
at org.testng.internal.TestMethodWorker.run(TestMethodWorker.java:128)
at java.base/java.util.ArrayList.forEach(ArrayList.java:1511)
at org.testng.TestRunner.privateRun(TestRunner.java:794)
at org.testng.TestRunner.run(TestRunner.java:596)
at org.testng.SuiteRunner.runTest(SuiteRunner.java:377)
at org.testng.SuiteRunner.runSequentially(SuiteRunner.java:371)
at org.testng.SuiteRunner.privateRun(SuiteRunner.java:332)
at org.testng.SuiteRunner.run(SuiteRunner.java:276)
at org.testng.SuiteRunnerWorker.runSuite(SuiteRunnerWorker.java:53)
at org.testng.SuiteRunnerWorker.run(SuiteRunnerWorker.java:96)
at org.testng.TestNG.runSuitesSequentially(TestNG.java:1212)
at org.testng.TestNG.runSuitesLocally(TestNG.java:1134)
at org.testng.TestNG.runSuites(TestNG.java:1063)
at org.testng.TestNG.run(TestNG.java:1031)
at org.testng.remote.AbstractRemoteTestNG.run(AbstractRemoteTestNG.java:115)
at org.testng.remote.RemoteTestNG.initAndRun(RemoteTestNG.java:251)
at org.testng.remote.RemoteTestNG.main(RemoteTestNG.java:77)
]]>
    </failure>
  </testcase> <!-- test1 -->
  <system-out/>
  <testcase classname="RetrylogictestNG.Rtrylogictestcase" name="test2" time="0.002">
    <skipped/>
  </testcase> <!-- test2 -->
  <system-out/>
  <testcase classname="RetrylogictestNG.Rtrylogictestcase" name="test2" time="0.011">
    <failure message="expected [sary] but found [selse]" type="java.lang.AssertionError">
      <![CDATA[java.lang.AssertionError: expected [sary] but found [selse]
at org.testng.Assert.fail(Assert.java:99)
at org.testng.Assert.failNotEquals(Assert.java:1037)
at org.testng.Assert.assertEqualsImpl(Assert.java:140)
at org.testng.Assert.assertEquals(Assert.java:122)
at org.testng.Assert.assertEquals(Assert.java:629)
at org.testng.Assert.assertEquals(Assert.java:639)
at RetrylogictestNG.Rtrylogictestcase.test2(Rtrylogictestcase.java:14)
at java.base/jdk.internal.reflect.NativeMethodAccessorImpl.invoke0(Native Method)
at java.base/jdk.internal.reflect.NativeMethodAccessorImpl.invoke(NativeMethodAccessorImpl.java:77)
at java.base/jdk.internal.reflect.DelegatingMethodAccessorImpl.invoke(DelegatingMethodAccessorImpl.java:43)
at java.base/java.lang.reflect.Method.invoke(Method.java:568)
at org.testng.internal.MethodInvocationHelper.invokeMethod(MethodInvocationHelper.java:133)
at org.testng.internal.TestInvoker.invokeMethod(TestInvoker.java:598)
at org.testng.internal.TestInvoker.retryFailed(TestInvoker.java:213)
at org.testng.internal.MethodRunner.runInSequence(MethodRunner.java:58)
at org.testng.internal.TestInvoker$MethodInvocationAgent.invoke(TestInvoker.java:824)
at org.testng.internal.TestInvoker.invokeTestMethods(TestInvoker.java:146)
at org.testng.internal.TestMethodWorker.invokeTestMethods(TestMethodWorker.java:146)
at org.testng.internal.TestMethodWorker.run(TestMethodWorker.java:128)
at java.base/java.util.ArrayList.forEach(ArrayList.java:1511)
at org.testng.TestRunner.privateRun(TestRunner.java:794)
at org.testng.TestRunner.run(TestRunner.java:596)
at org.testng.SuiteRunner.runTest(SuiteRunner.java:377)
at org.testng.SuiteRunner.runSequentially(SuiteRunner.java:371)
at org.testng.SuiteRunner.privateRun(SuiteRunner.java:332)
at org.testng.SuiteRunner.run(SuiteRunner.java:276)
at org.testng.SuiteRunnerWorker.runSuite(SuiteRunnerWorker.java:53)
at org.testng.SuiteRunnerWorker.run(SuiteRunnerWorker.java:96)
at org.testng.TestNG.runSuitesSequentially(TestNG.java:1212)
at org.testng.TestNG.runSuitesLocally(TestNG.java:1134)
at org.testng.TestNG.runSuites(TestNG.java:1063)
at org.testng.TestNG.run(TestNG.java:1031)
at org.testng.remote.AbstractRemoteTestNG.run(AbstractRemoteTestNG.java:115)
at org.testng.remote.RemoteTestNG.initAndRun(RemoteTestNG.java:251)
at org.testng.remote.RemoteTestNG.main(RemoteTestNG.java:77)
]]>
    </failure>
  </testcase> <!-- test2 -->
  <system-out/>
  <testcase classname="RetrylogictestNG.Rtrylogictestcase" name="test2" time="0.002">
    <skipped/>
  </testcase> <!-- test2 -->
  <system-out/>
</testsuite> <!-- RetrylogictestNG.Rtrylogictestcase -->
